[2023-10-29T02:11:26.961+0000] {taskinstance.py:1159} INFO - Dependencies all met for dep_context=non-requeueable deps ti=<TaskInstance: zillow_analytics_dag.tsk_transfer_s3_to_redshift scheduled__2023-10-28T00:00:00+00:00 [queued]>
[2023-10-29T02:11:26.968+0000] {taskinstance.py:1159} INFO - Dependencies all met for dep_context=requeueable deps ti=<TaskInstance: zillow_analytics_dag.tsk_transfer_s3_to_redshift scheduled__2023-10-28T00:00:00+00:00 [queued]>
[2023-10-29T02:11:26.969+0000] {taskinstance.py:1361} INFO - Starting attempt 2 of 3
[2023-10-29T02:11:26.984+0000] {taskinstance.py:1382} INFO - Executing <Task(S3ToRedshiftOperator): tsk_transfer_s3_to_redshift> on 2023-10-28 00:00:00+00:00
[2023-10-29T02:11:26.987+0000] {standard_task_runner.py:57} INFO - Started process 7327 to run task
[2023-10-29T02:11:26.990+0000] {standard_task_runner.py:84} INFO - Running: ['airflow', 'tasks', 'run', 'zillow_analytics_dag', 'tsk_transfer_s3_to_redshift', 'scheduled__2023-10-28T00:00:00+00:00', '--job-id', '15', '--raw', '--subdir', 'DAGS_FOLDER/analytics.py', '--cfg-path', '/tmp/tmp_vf7tb46']
[2023-10-29T02:11:26.991+0000] {standard_task_runner.py:85} INFO - Job 15: Subtask tsk_transfer_s3_to_redshift
[2023-10-29T02:11:27.030+0000] {task_command.py:416} INFO - Running <TaskInstance: zillow_analytics_dag.tsk_transfer_s3_to_redshift scheduled__2023-10-28T00:00:00+00:00 [running]> on host ip-172-31-56-104.ec2.internal
[2023-10-29T02:11:27.091+0000] {taskinstance.py:1662} INFO - Exporting env vars: AIRFLOW_CTX_DAG_EMAIL='chattisowmya@gmail.com' AIRFLOW_CTX_DAG_OWNER='airflow' AIRFLOW_CTX_DAG_ID='zillow_analytics_dag' AIRFLOW_CTX_TASK_ID='tsk_transfer_s3_to_redshift' AIRFLOW_CTX_EXECUTION_DATE='2023-10-28T00:00:00+00:00' AIRFLOW_CTX_TRY_NUMBER='2' AIRFLOW_CTX_DAG_RUN_ID='scheduled__2023-10-28T00:00:00+00:00'
[2023-10-29T02:11:27.098+0000] {taskinstance.py:1937} ERROR - Task failed with exception
Traceback (most recent call last):
  File "/home/ubuntu/env/lib/python3.10/site-packages/airflow/providers/amazon/aws/transfers/s3_to_redshift.py", line 144, in execute
    conn = S3Hook.get_connection(conn_id=self.aws_conn_id)
  File "/home/ubuntu/env/lib/python3.10/site-packages/airflow/hooks/base.py", line 72, in get_connection
    conn = Connection.get_connection_from_secrets(conn_id)
  File "/home/ubuntu/env/lib/python3.10/site-packages/airflow/models/connection.py", line 477, in get_connection_from_secrets
    raise AirflowNotFoundException(f"The conn_id `{conn_id}` isn't defined")
airflow.exceptions.AirflowNotFoundException: The conn_id `aws_s3_conn` isn't defined
[2023-10-29T02:11:27.101+0000] {taskinstance.py:1400} INFO - Marking task as UP_FOR_RETRY. dag_id=zillow_analytics_dag, task_id=tsk_transfer_s3_to_redshift, execution_date=20231028T000000, start_date=20231029T021126, end_date=20231029T021127
[2023-10-29T02:11:27.114+0000] {standard_task_runner.py:104} ERROR - Failed to execute job 15 for task tsk_transfer_s3_to_redshift (The conn_id `aws_s3_conn` isn't defined; 7327)
[2023-10-29T02:11:27.121+0000] {local_task_job_runner.py:228} INFO - Task exited with return code 1
[2023-10-29T02:11:27.135+0000] {taskinstance.py:2778} INFO - 0 downstream tasks scheduled from follow-on schedule check
